Workbook

Sheet Dashboard
B2: Pixel & Pastry Media | 2026 Bookkeeping Dashboard
B3: Prepared by Blackthorn Ledger • Simulated portfolio case study • January–December 2026
B5: Total Revenue | E5: Total Expenses | H5: Net Income | K5: Profit Margin
B6: =$C$23 -> 77602 | E6: =$D$23 -> 16650 | H6: =$E$23 -> 60952 | K6: =IFERROR($E$23/$C$23,0) -> 0.78544367
B10: Month | C10: Revenue | D10: Expenses | E10: Net Income
B11: 46023 | C11: =SUMIFS(Transactions!$I:$I,Transactions!$B:$B,">="&$B11,Transactions!$B:$B,"<"&EDATE($B11,1)) -> 3995 | D11: =SUMIFS(Transactions!$J:$J,Transactions!$B:$B,">="&$B11,Transactions!$B:$B,"<"&EDATE($B11,1)) -> 1566 | E11: =C11-D11 -> 2429
B12: 46054 | C12: =SUMIFS(Transactions!$I:$I,Transactions!$B:$B,">="&$B12,Transactions!$B:$B,"<"&EDATE($B12,1)) -> 4622 | D12: =SUMIFS(Transactions!$J:$J,Transactions!$B:$B,">="&$B12,Transactions!$B:$B,"<"&EDATE($B12,1)) -> 1157 | E12: =C12-D12 -> 3465
B13: 46082 | C13: =SUMIFS(Transactions!$I:$I,Transactions!$B:$B,">="&$B13,Transactions!$B:$B,"<"&EDATE($B13,1)) -> 5273 | D13: =SUMIFS(Transactions!$J:$J,Transactions!$B:$B,">="&$B13,Transactions!$B:$B,"<"&EDATE($B13,1)) -> 1970 | E13: =C13-D13 -> 3303
B14: 46113 | C14: =SUMIFS(Transactions!$I:$I,Transactions!$B:$B,">="&$B14,Transactions!$B:$B,"<"&EDATE($B14,1)) -> 5561 | D14: =SUMIFS(Transactions!$J:$J,Transactions!$B:$B,">="&$B14,Transactions!$B:$B,"<"&EDATE($B14,1)) -> 2084 | E14: =C14-D14 -> 3477
B15: 46143 | C15: =SUMIFS(Transactions!$I:$I,Transactions!$B:$B,">="&$B15,Transactions!$B:$B,"<"&EDATE($B15,1)) -> 5809 | D15: =SUMIFS(Transactions!$J:$J,Transactions!$B:$B,">="&$B15,Transactions!$B:$B,"<"&EDATE($B15,1)) -> 1001 | E15: =C15-D15 -> 4808
B16: 46174 | C16: =SUMIFS(Transactions!$I:$I,Transactions!$B:$B,">="&$B16,Transactions!$B:$B,"<"&EDATE($B16,1)) -> 6127 | D16: =SUMIFS(Transactions!$J:$J,Transactions!$B:$B,">="&$B16,Transactions!$B:$B,"<"&EDATE($B16,1)) -> 626 | E16: =C16-D16 -> 5501
B17: 46204 | C17: =SUMIFS(Transactions!$I:$I,Transactions!$B:$B,">="&$B17,Transactions!$B:$B,"<"&EDATE($B17,1)) -> 6535 | D17: =SUMIFS(Transactions!$J:$J,Transactions!$B:$B,">="&$B17,Transactions!$B:$B,"<"&EDATE($B17,1)) -> 1063 | E17: =C17-D17 -> 5472
B18: 46235 | C18: =SUMIFS(Transactions!$I:$I,Transactions!$B:$B,">="&$B18,Transactions!$B:$B,"<"&EDATE($B18,1)) -> 6955 | D18: =SUMIFS(Transactions!$J:$J,Transactions!$B:$B,">="&$B18,Transactions!$B:$B,"<"&EDATE($B18,1)) -> 695 | E18: =C18-D18 -> 6260
B19: 46266 | C19: =SUMIFS(Transactions!$I:$I,Transactions!$B:$B,">="&$B19,Transactions!$B:$B,"<"&EDATE($B19,1)) -> 7370 | D19: =SUMIFS(Transactions!$J:$J,Transactions!$B:$B,">="&$B19,Transactions!$B:$B,"<"&EDATE($B19,1)) -> 1172 | E19: =C19-D19 -> 6198
B20: 46296 | C20: =SUMIFS(Transactions!$I:$I,Transactions!$B:$B,">="&$B20,Transactions!$B:$B,"<"&EDATE($B20,1)) -> 7800 | D20: =SUMIFS(Transactions!$J:$J,Transactions!$B:$B,">="&$B20,Transactions!$B:$B,"<"&EDATE($B20,1)) -> 1351 | E20: =C20-D20 -> 6449
B21: 46327 | C21: =SUMIFS(Transactions!$I:$I,Transactions!$B:$B,">="&$B21,Transactions!$B:$B,"<"&EDATE($B21,1)) -> 8350 | D21: =SUMIFS(Transactions!$J:$J,Transactions!$B:$B,">="&$B21,Transactions!$B:$B,"<"&EDATE($B21,1)) -> 2037 | E21: =C21-D21 -> 6313
B22: 46357 | C22: =SUMIFS(Transactions!$I:$I,Transactions!$B:$B,">="&$B22,Transactions!$B:$B,"<"&EDATE($B22,1)) -> 9205 | D22: =SUMIFS(Transactions!$J:$J,Transactions!$B:$B,">="&$B22,Transactions!$B:$B,"<"&EDATE($B22,1)) -> 1928 | E22: =C22-D22 -> 7277
B23: Annual Total | C23: =SUM(C11:C22) -> 77602 | D23: =SUM(D11:D22) -> 16650 | E23: =SUM(E11:E22) -> 60952
B26: Revenue Stream | C26: Annual Revenue | D26: Mix
B27: Subscriptions | C27: {=SUMIF(Transactions!$G:$G,B27:B32,Transactions!$I:$I)} -> 24610 | D27: {=IFERROR(C27:C32/$C$33,0)} -> 0.317131
B28: Donations & Tips | C28: 7165 | D28: 0.092330095
B29: Sponsorships | C29: 27750 | D29: 0.35759388
B30: Merchandise | C30: 11855 | D30: 0.15276668
B31: Affiliate Revenue | C31: 2192 | D31: 0.028246695
B32: Ad Revenue | C32: 4030 | D32: 0.051931651
B33: Total | C33: =SUM(C27:C32) -> 77602 | D33: =SUM(D27:D32) -> 1
B36: Audit Check | C36: Ledger | D36: Report | E36: Difference | F36: Status
B37: Revenue tie-out | C37: {={SUM(Transactions!$I:$I);SUM(Transactions!$J:$J);SUM(Transactions!$I:$I)-SUM(Transactions!$J:$J);COUNTIFS(Transactions!$A:$A,"TX-*",Transactions!$G:$G,"");COUNTIF(Transactions!$N:$N,">0")}} -> 77602 | D37: {={$C$23;$D$23;$E$23;0;0}} -> 77602 | E37: {=C37:C41-D37:D41} -> 0 | F37: {=IF(ABS(E37:E41)<0.01,"PASS","REVIEW")} -> PASS
B38: Expense tie-out | C38: 16650 | D38: 16650 | E38: 0 | F38: PASS
B39: Net income tie-out | C39: 60952 | D39: 60952 | E39: 0 | F39: PASS
B40: Uncategorized transactions | C40: 0 | D40: 0 | E40: 0 | F40: PASS
B41: Duplicate transaction IDs | C41: 0 | D41: 0 | E41: 0 | F41: PASS

Sheet Monthly P&L
A2: Monthly Profit & Loss | B2: 46023 | C2: 46054 | D2: 46082 | E2: Q1 Total
A4: Revenue
A5: Subscriptions | B5: =SUMIFS(Transactions!$I$2:$I$54,Transactions!$C$2:$C$54,B$2,Transactions!$G$2:$G$54,$A5) -> 1450 | C5: =SUMIFS(Transactions!$I$2:$I$54,Transactions!$C$2:$C$54,C$2,Transactions!$G$2:$G$54,$A5) -> 1580 | D5: =SUMIFS(Transactions!$I$2:$I$54,Transactions!$C$2:$C$54,D$2,Transactions!$G$2:$G$54,$A5) -> 1710 | E5: =SUM(B5:D5) -> 4740
A6: Donations & Tips | B6: =SUMIFS(Transactions!$I$2:$I$54,Transactions!$C$2:$C$54,B$2,Transactions!$G$2:$G$54,$A6) -> 380 | C6: =SUMIFS(Transactions!$I$2:$I$54,Transactions!$C$2:$C$54,C$2,Transactions!$G$2:$G$54,$A6) -> 445 | D6: =SUMIFS(Transactions!$I$2:$I$54,Transactions!$C$2:$C$54,D$2,Transactions!$G$2:$G$54,$A6) -> 510 | E6: =SUM(B6:D6) -> 1335
A7: Sponsorships | B7: =SUMIFS(Transactions!$I$2:$I$54,Transactions!$C$2:$C$54,B$2,Transactions!$G$2:$G$54,$A7) -> 1200 | C7: =SUMIFS(Transactions!$I$2:$I$54,Transactions!$C$2:$C$54,C$2,Transactions!$G$2:$G$54,$A7) -> 1500 | D7: =SUMIFS(Transactions!$I$2:$I$54,Transactions!$C$2:$C$54,D$2,Transactions!$G$2:$G$54,$A7) -> 1850 | E7: =SUM(B7:D7) -> 4550
A8: Merchandise | B8: =SUMIFS(Transactions!$I$2:$I$54,Transactions!$C$2:$C$54,B$2,Transactions!$G$2:$G$54,$A8) -> 640 | C8: =SUMIFS(Transactions!$I$2:$I$54,Transactions!$C$2:$C$54,C$2,Transactions!$G$2:$G$54,$A8) -> 720 | D8: =SUMIFS(Transactions!$I$2:$I$54,Transactions!$C$2:$C$54,D$2,Transactions!$G$2:$G$54,$A8) -> 790 | E8: =SUM(B8:D8) -> 2150
A9: Affiliate Revenue | B9: =SUMIFS(Transactions!$I$2:$I$54,Transactions!$C$2:$C$54,B$2,Transactions!$G$2:$G$54,$A9) -> 115 | C9: =SUMIFS(Transactions!$I$2:$I$54,Transactions!$C$2:$C$54,C$2,Transactions!$G$2:$G$54,$A9) -> 132 | D9: =SUMIFS(Transactions!$I$2:$I$54,Transactions!$C$2:$C$54,D$2,Transactions!$G$2:$G$54,$A9) -> 148 | E9: =SUM(B9:D9) -> 395
A10: Ad Revenue | B10: =SUMIFS(Transactions!$I$2:$I$54,Transactions!$C$2:$C$54,B$2,Transactions!$G$2:$G$54,$A10) -> 210 | C10: =SUMIFS(Transactions!$I$2:$I$54,Transactions!$C$2:$C$54,C$2,Transactions!$G$2:$G$54,$A10) -> 245 | D10: =SUMIFS(Transactions!$I$2:$I$54,Transactions!$C$2:$C$54,D$2,Transactions!$G$2:$G$54,$A10) -> 265 | E10: =SUM(B10:D10) -> 720
A11: Total Revenue | B11: =SUM(B5:B10) -> 3995 | C11: =SUM(C5:C10) -> 4622 | D11: =SUM(D5:D10) -> 5273 | E11: =SUM(E5:E10) -> 13890
A13: Expenses
A14: Platform Fees | B14: =SUMIFS(Transactions!$J$2:$J$54,Transactions!$C$2:$C$54,B$2,Transactions!$G$2:$G$54,$A14) -> 210 | C14: =SUMIFS(Transactions!$J$2:$J$54,Transactions!$C$2:$C$54,C$2,Transactions!$G$2:$G$54,$A14) -> 230 | D14: =SUMIFS(Transactions!$J$2:$J$54,Transactions!$C$2:$C$54,D$2,Transactions!$G$2:$G$54,$A14) -> 240 | E14: =SUM(B14:D14) -> 680
A15: Payment Processing | B15: =SUMIFS(Transactions!$J$2:$J$54,Transactions!$C$2:$C$54,B$2,Transactions!$G$2:$G$54,$A15) -> 18 | C15: =SUMIFS(Transactions!$J$2:$J$54,Transactions!$C$2:$C$54,C$2,Transactions!$G$2:$G$54,$A15) -> 22 | D15: =SUMIFS(Transactions!$J$2:$J$54,Transactions!$C$2:$C$54,D$2,Transactions!$G$2:$G$54,$A15) -> 26 | E15: =SUM(B15:D15) -> 66
A16: Software Subscriptions | B16: =SUMIFS(Transactions!$J$2:$J$54,Transactions!$C$2:$C$54,B$2,Transactions!$G$2:$G$54,$A16) -> 99 | C16: =SUMIFS(Transactions!$J$2:$J$54,Transactions!$C$2:$C$54,C$2,Transactions!$G$2:$G$54,$A16) -> 99 | D16: =SUMIFS(Transactions!$J$2:$J$54,Transactions!$C$2:$C$54,D$2,Transactions!$G$2:$G$54,$A16) -> 99 | E16: =SUM(B16:D16) -> 297
A17: Equipment | B17: =SUMIFS(Transactions!$J$2:$J$54,Transactions!$C$2:$C$54,B$2,Transactions!$G$2:$G$54,$A17) -> 520 | C17: =SUMIFS(Transactions!$J$2:$J$54,Transactions!$C$2:$C$54,C$2,Transactions!$G$2:$G$54,$A17) -> 0 | D17: =SUMIFS(Transactions!$J$2:$J$54,Transactions!$C$2:$C$54,D$2,Transactions!$G$2:$G$54,$A17) -> 680 | E17: =SUM(B17:D17) -> 1200
A18: Content & Games | B18: =SUMIFS(Transactions!$J$2:$J$54,Transactions!$C$2:$C$54,B$2,Transactions!$G$2:$G$54,$A18) -> 95 | C18: =SUMIFS(Transactions!$J$2:$J$54,Transactions!$C$2:$C$54,C$2,Transactions!$G$2:$G$54,$A18) -> 110 | D18: =SUMIFS(Transactions!$J$2:$J$54,Transactions!$C$2:$C$54,D$2,Transactions!$G$2:$G$54,$A18) -> 130 | E18: =SUM(B18:D18) -> 335
A19: Internet | B19: =SUMIFS(Transactions!$J$2:$J$54,Transactions!$C$2:$C$54,B$2,Transactions!$G$2:$G$54,$A19) -> 120 | C19: =SUMIFS(Transactions!$J$2:$J$54,Transactions!$C$2:$C$54,C$2,Transactions!$G$2:$G$54,$A19) -> 120 | D19: =SUMIFS(Transactions!$J$2:$J$54,Transactions!$C$2:$C$54,D$2,Transactions!$G$2:$G$54,$A19) -> 120 | E19: =SUM(B19:D19) -> 360
A20: Advertising | B20: =SUMIFS(Transactions!$J$2:$J$54,Transactions!$C$2:$C$54,B$2,Transactions!$G$2:$G$54,$A20) -> 350 | C20: =SUMIFS(Transactions!$J$2:$J$54,Transactions!$C$2:$C$54,C$2,Transactions!$G$2:$G$54,$A20) -> 425 | D20: =SUMIFS(Transactions!$J$2:$J$54,Transactions!$C$2:$C$54,D$2,Transactions!$G$2:$G$54,$A20) -> 475 | E20: =SUM(B20:D20) -> 1250
A21: Contractor Services | B21: =SUMIFS(Transactions!$J$2:$J$54,Transactions!$C$2:$C$54,B$2,Transactions!$G$2:$G$54,$A21) -> 62 | C21: =SUMIFS(Transactions!$J$2:$J$54,Transactions!$C$2:$C$54,C$2,Transactions!$G$2:$G$54,$A21) -> 78 | D21: =SUMIFS(Transactions!$J$2:$J$54,Transactions!$C$2:$C$54,D$2,Transactions!$G$2:$G$54,$A21) -> 92 | E21: =SUM(B21:D21) -> 232
A22: Shipping & Postage | B22: =SUMIFS(Transactions!$J$2:$J$54,Transactions!$C$2:$C$54,B$2,Transactions!$G$2:$G$54,$A22) -> 44 | C22: =SUMIFS(Transactions!$J$2:$J$54,Transactions!$C$2:$C$54,C$2,Transactions!$G$2:$G$54,$A22) -> 38 | D22: =SUMIFS(Transactions!$J$2:$J$54,Transactions!$C$2:$C$54,D$2,Transactions!$G$2:$G$54,$A22) -> 51 | E22: =SUM(B22:D22) -> 133
A23: Office Supplies | B23: =SUMIFS(Transactions!$J$2:$J$54,Transactions!$C$2:$C$54,B$2,Transactions!$G$2:$G$54,$A23) -> 48 | C23: =SUMIFS(Transactions!$J$2:$J$54,Transactions!$C$2:$C$54,C$2,Transactions!$G$2:$G$54,$A23) -> 35 | D23: =SUMIFS(Transactions!$J$2:$J$54,Transactions!$C$2:$C$54,D$2,Transactions!$G$2:$G$54,$A23) -> 57 | E23: =SUM(B23:D23) -> 140
A24: Total Expenses | B24: =SUM(B14:B23) -> 1566 | C24: =SUM(C14:C23) -> 1157 | D24: =SUM(D14:D23) -> 1970 | E24: =SUM(E14:E23) -> 4693
A26: Net Income | B26: =B11-B24 -> 2429 | C26: =C11-C24 -> 3465 | D26: =D11-D24 -> 3303 | E26: =E11-E24 -> 9197
A27: Profit Margin | B27: =IFERROR(B26/B11,0) -> 0.60801001 | C27: =IFERROR(C26/C11,0) -> 0.74967547 | D27: =IFERROR(D26/D11,0) -> 0.62639863 | E27: =IFERROR(E26/E11,0) -> 0.66213103
A32: Monthly Profit & Loss | B32: 46113 | C32: 46143 | D32: 46174 | E32: Q2 Total
A34: Revenue
A35: Subscriptions | B35: =SUMIFS(Transactions!$I:$I,Transactions!$C:$C,B$32,Transactions!$G:$G,$A35) -> 1765 | C35: =SUMIFS(Transactions!$I:$I,Transactions!$C:$C,C$32,Transactions!$G:$G,$A35) -> 1840 | D35: =SUMIFS(Transactions!$I:$I,Transactions!$C:$C,D$32,Transactions!$G:$G,$A35) -> 1925 | E35: =SUM(B35:D35) -> 5530
A36: Donations & Tips | B36: =SUMIFS(Transactions!$I:$I,Transactions!$C:$C,B$32,Transactions!$G:$G,$A36) -> 535 | C36: =SUMIFS(Transactions!$I:$I,Transactions!$C:$C,C$32,Transactions!$G:$G,$A36) -> 490 | D36: =SUMIFS(Transactions!$I:$I,Transactions!$C:$C,D$32,Transactions!$G:$G,$A36) -> 560 | E36: =SUM(B36:D36) -> 1585
A37: Sponsorships | B37: =SUMIFS(Transactions!$I:$I,Transactions!$C:$C,B$32,Transactions!$G:$G,$A37) -> 2000 | C37: =SUMIFS(Transactions!$I:$I,Transactions!$C:$C,C$32,Transactions!$G:$G,$A37) -> 2150 | D37: =SUMIFS(Transactions!$I:$I,Transactions!$C:$C,D$32,Transactions!$G:$G,$A37) -> 2250 | E37: =SUM(B37:D37) -> 6400
A38: Merchandise | B38: =SUMIFS(Transactions!$I:$I,Transactions!$C:$C,B$32,Transactions!$G:$G,$A38) -> 825 | C38: =SUMIFS(Transactions!$I:$I,Transactions!$C:$C,C$32,Transactions!$G:$G,$A38) -> 870 | D38: =SUMIFS(Transactions!$I:$I,Transactions!$C:$C,D$32,Transactions!$G:$G,$A38) -> 910 | E38: =SUM(B38:D38) -> 2605
A39: Affiliate Revenue | B39: =SUMIFS(Transactions!$I:$I,Transactions!$C:$C,B$32,Transactions!$G:$G,$A39) -> 156 | C39: =SUMIFS(Transactions!$I:$I,Transactions!$C:$C,C$32,Transactions!$G:$G,$A39) -> 164 | D39: =SUMIFS(Transactions!$I:$I,Transactions!$C:$C,D$32,Transactions!$G:$G,$A39) -> 172 | E39: =SUM(B39:D39) -> 492
A40: Ad Revenue | B40: =SUMIFS(Transactions!$I:$I,Transactions!$C:$C,B$32,Transactions!$G:$G,$A40) -> 280 | C40: =SUMIFS(Transactions!$I:$I,Transactions!$C:$C,C$32,Transactions!$G:$G,$A40) -> 295 | D40: =SUMIFS(Transactions!$I:$I,Transactions!$C:$C,D$32,Transactions!$G:$G,$A40) -> 310 | E40: =SUM(B40:D40) -> 885
A41: Total Revenue | B41: =SUM(B35:B40) -> 5561 | C41: =SUM(C35:C40) -> 5809 | D41: =SUM(D35:D40) -> 6127 | E41: =SUM(E35:E40) -> 17497
A43: Expenses
A44: Platform Fees | B44: =SUMIFS(Transactions!$J:$J,Transactions!$C:$C,B$32,Transactions!$G:$G,$A44) -> 248 | C44: =SUMIFS(Transactions!$J:$J,Transactions!$C:$C,C$32,Transactions!$G:$G,$A44) -> 258 | D44: =SUMIFS(Transactions!$J:$J,Transactions!$C:$C,D$32,Transactions!$G:$G,$A44) -> 270 | E44: =SUM(B44:D44) -> 776
A45: Payment Processing | B45: =SUMIFS(Transactions!$J:$J,Transactions!$C:$C,B$32,Transactions!$G:$G,$A45) -> 27 | C45: =SUMIFS(Transactions!$J:$J,Transactions!$C:$C,C$32,Transactions!$G:$G,$A45) -> 29 | D45: =SUMIFS(Transactions!$J:$J,Transactions!$C:$C,D$32,Transactions!$G:$G,$A45) -> 31 | E45: =SUM(B45:D45) -> 87
A46: Software Subscriptions | B46: =SUMIFS(Transactions!$J:$J,Transactions!$C:$C,B$32,Transactions!$G:$G,$A46) -> 99 | C46: =SUMIFS(Transactions!$J:$J,Transactions!$C:$C,C$32,Transactions!$G:$G,$A46) -> 84 | D46: =SUMIFS(Transactions!$J:$J,Transactions!$C:$C,D$32,Transactions!$G:$G,$A46) -> 70 | E46: =SUM(B46:D46) -> 253
A47: Equipment | B47: =SUMIFS(Transactions!$J:$J,Transactions!$C:$C,B$32,Transactions!$G:$G,$A47) -> 740 | C47: =SUMIFS(Transactions!$J:$J,Transactions!$C:$C,C$32,Transactions!$G:$G,$A47) -> 0 | D47: =SUMIFS(Transactions!$J:$J,Transactions!$C:$C,D$32,Transactions!$G:$G,$A47) -> 0 | E47: =SUM(B47:D47) -> 740
A48: Content & Games | B48: =SUMIFS(Transactions!$J:$J,Transactions!$C:$C,B$32,Transactions!$G:$G,$A48) -> 135 | C48: =SUMIFS(Transactions!$J:$J,Transactions!$C:$C,C$32,Transactions!$G:$G,$A48) -> 0 | D48: =SUMIFS(Transactions!$J:$J,Transactions!$C:$C,D$32,Transactions!$G:$G,$A48) -> 145 | E48: =SUM(B48:D48) -> 280
A49: Internet | B49: =SUMIFS(Transactions!$J:$J,Transactions!$C:$C,B$32,Transactions!$G:$G,$A49) -> 120 | C49: =SUMIFS(Transactions!$J:$J,Transactions!$C:$C,C$32,Transactions!$G:$G,$A49) -> 120 | D49: =SUMIFS(Transactions!$J:$J,Transactions!$C:$C,D$32,Transactions!$G:$G,$A49) -> 0 | E49: =SUM(B49:D49) -> 240
A50: Advertising | B50: =SUMIFS(Transactions!$J:$J,Transactions!$C:$C,B$32,Transactions!$G:$G,$A50) -> 495 | C50: =SUMIFS(Transactions!$J:$J,Transactions!$C:$C,C$32,Transactions!$G:$G,$A50) -> 510 | D50: =SUMIFS(Transactions!$J:$J,Transactions!$C:$C,D$32,Transactions!$G:$G,$A50) -> 0 | E50: =SUM(B50:D50) -> 1005
...

Sheet Transactions
A1: Transaction ID | B1: Date | C1: Month | D1: Description | E1: Account | F1: Type | G1: Category | H1: Revenue Stream | I1: Inflow | J1: Outflow | K1: Net Amount | L1: Reconciled | M1: Notes | N1: Duplicate Flag | O1: Quarter
A2: TX-1009 | B2: 46024 | C2: Jan 2026 | D2: Adobe Creative Cloud | E2: Credit Card | F2: Expense | G2: Software Subscriptions | I2: 0 | J2: 55 | K2: =I2-J2 -> -55 | L2: Yes | N2: =IF(COUNTIF($A$2:$A$54,A2)>1,1,0) -> 0 | O2: ="Q"&ROUNDUP(MONTH($B2)/3,0) -> Q1
A3: TX-1001 | B3: 46025 | C3: Jan 2026 | D3: Twitch monthly payout | E3: Checking | F3: Revenue | G3: Subscriptions | H3: Twitch | I3: 1450 | J3: 0 | K3: =I3-J3 -> 1450 | L3: Yes | N3: =IF(COUNTIF($A$2:$A$54,A3)>1,1,0) -> 0 | O3: ==IF($B2="","", "Q"&ROUNDUP(MONTH($B2)/3,0)) -> #ERROR!
A4: TX-1007 | B4: 46026 | C4: Jan 2026 | D4: Twitch platform service fees | E4: Checking | F4: Expense | G4: Platform Fees | I4: 0 | J4: 210 | K4: =I4-J4 -> -210 | L4: Yes | N4: =IF(COUNTIF($A$2:$A$54,A4)>1,1,0) -> 0 | O4: ="Q"&ROUNDUP(MONTH($B4)/3,0) -> Q1
A5: TX-1002 | B5: 46027 | C5: Jan 2026 | D5: Streamlabs creator tips | E5: PayPal | F5: Revenue | G5: Donations & Tips | H5: Donations | I5: 380 | J5: 0 | K5: =I5-J5 -> 380 | L5: Yes | N5: =IF(COUNTIF($A$2:$A$54,A5)>1,1,0) -> 0 | O5: ="Q"&ROUNDUP(MONTH($B5)/3,0) -> Q1
A6: TX-1010 | B6: 46029 | C6: Jan 2026 | D6: StreamYard subscription | E6: Credit Card | F6: Expense | G6: Software Subscriptions | I6: 0 | J6: 29 | K6: =I6-J6 -> -29 | L6: Yes | N6: =IF(COUNTIF($A$2:$A$54,A6)>1,1,0) -> 0 | O6: ="Q"&ROUNDUP(MONTH($B6)/3,0) -> Q1
A7: TX-1003 | B7: 46030 | C7: Jan 2026 | D7: Sponsored stream campaign | E7: Checking | F7: Revenue | G7: Sponsorships | H7: Brand Partnership | I7: 1200 | J7: 0 | K7: =I7-J7 -> 1200 | L7: Yes | N7: =IF(COUNTIF($A$2:$A$54,A7)>1,1,0) -> 0 | O7: ="Q"&ROUNDUP(MONTH($B7)/3,0) -> Q1
A8: TX-1011 | B8: 46031 | C8: Jan 2026 | D8: Canva Pro subscription | E8: Credit Card | F8: Expense | G8: Software Subscriptions | I8: 0 | J8: 15 | K8: =I8-J8 -> -15 | L8: Yes | N8: =IF(COUNTIF($A$2:$A$54,A8)>1,1,0) -> 0 | O8: ="Q"&ROUNDUP(MONTH($B8)/3,0) -> Q1
A9: TX-1012 | B9: 46033 | C9: Jan 2026 | D9: Streaming camera and light kit | E9: Credit Card | F9: Expense | G9: Equipment | I9: 0 | J9: 520 | K9: =I9-J9 -> -520 | L9: Yes | M9: Capital purchase documented | N9: =IF(COUNTIF($A$2:$A$54,A9)>1,1,0) -> 0 | O9: ="Q"&ROUNDUP(MONTH($B9)/3,0) -> Q1
A10: TX-1004 | B10: 46034 | C10: Jan 2026 | D10: Shopify merchandise settlement | E10: Checking | F10: Revenue | G10: Merchandise | H10: Online Store | I10: 640 | J10: 0 | K10: =I10-J10 -> 640 | L10: Yes | N10: =IF(COUNTIF($A$2:$A$54,A10)>1,1,0) -> 0 | O10: ="Q"&ROUNDUP(MONTH($B10)/3,0) -> Q1
A11: TX-1008 | B11: 46034 | C11: Jan 2026 | D11: Stripe processing fees | E11: Checking | F11: Expense | G11: Payment Processing | I11: 0 | J11: 18 | K11: =I11-J11 -> -18 | L11: Yes | N11: =IF(COUNTIF($A$2:$A$54,A11)>1,1,0) -> 0 | O11: ="Q"&ROUNDUP(MONTH($B11)/3,0) -> Q1
A12: TX-1005 | B12: 46037 | C12: Jan 2026 | D12: Amazon affiliate payout | E12: Checking | F12: Revenue | G12: Affiliate Revenue | H12: Affiliate | I12: 115 | J12: 0 | K12: =I12-J12 -> 115 | L12: Yes | N12: =IF(COUNTIF($A$2:$A$54,A12)>1,1,0) -> 0 | O12: ="Q"&ROUNDUP(MONTH($B12)/3,0) -> Q1
A13: TX-1013 | B13: 46038 | C13: Jan 2026 | D13: Games and stream content | E13: Credit Card | F13: Expense | G13: Content & Games | I13: 0 | J13: 95 | K13: =I13-J13 -> -95 | L13: Yes | N13: =IF(COUNTIF($A$2:$A$54,A13)>1,1,0) -> 0 | O13: ="Q"&ROUNDUP(MONTH($B13)/3,0) -> Q1
A14: TX-1014 | B14: 46040 | C14: Jan 2026 | D14: Business internet allocation | E14: Checking | F14: Expense | G14: Internet | I14: 0 | J14: 120 | K14: =I14-J14 -> -120 | L14: Yes | M14: Business-use portion | N14: =IF(COUNTIF($A$2:$A$54,A14)>1,1,0) -> 0 | O14: ="Q"&ROUNDUP(MONTH($B14)/3,0) -> Q1
A15: TX-1006 | B15: 46042 | C15: Jan 2026 | D15: YouTube advertising payout | E15: Checking | F15: Revenue | G15: Ad Revenue | H15: YouTube | I15: 210 | J15: 0 | K15: =I15-J15 -> 210 | L15: Yes | N15: =IF(COUNTIF($A$2:$A$54,A15)>1,1,0) -> 0 | O15: ="Q"&ROUNDUP(MONTH($B15)/3,0) -> Q1
A16: TX-1015 | B16: 46044 | C16: Jan 2026 | D16: Social media campaign | E16: Credit Card | F16: Expense | G16: Advertising | I16: 0 | J16: 350 | K16: =I16-J16 -> -350 | L16: Yes | N16: =IF(COUNTIF($A$2:$A$54,A16)>1,1,0) -> 0 | O16: ="Q"&ROUNDUP(MONTH($B16)/3,0) -> Q1
A17: TX-1016 | B17: 46047 | C17: Jan 2026 | D17: Freelance video editing | E17: Checking | F17: Expense | G17: Contractor Services | I17: 0 | J17: 62 | K17: =I17-J17 -> -62 | L17: Yes | N17: =IF(COUNTIF($A$2:$A$54,A17)>1,1,0) -> 0 | O17: ="Q"&ROUNDUP(MONTH($B17)/3,0) -> Q1
A18: TX-1017 | B18: 46049 | C18: Jan 2026 | D18: Merchandise shipping labels | E18: Checking | F18: Expense | G18: Shipping & Postage | I18: 0 | J18: 44 | K18: =I18-J18 -> -44 | L18: Yes | N18: =IF(COUNTIF($A$2:$A$54,A18)>1,1,0) -> 0 | O18: ="Q"&ROUNDUP(MONTH($B18)/3,0) -> Q1
A19: TX-1018 | B19: 46050 | C19: Jan 2026 | D19: Packaging and printer supplies | E19: Credit Card | F19: Expense | G19: Office Supplies | I19: 0 | J19: 48 | K19: =I19-J19 -> -48 | L19: Yes | N19: =IF(COUNTIF($A$2:$A$54,A19)>1,1,0) -> 0 | O19: ="Q"&ROUNDUP(MONTH($B19)/3,0) -> Q1
A20: TX-1027 | B20: 46055 | C20: Feb 2026 | D20: Adobe Creative Cloud | E20: Credit Card | F20: Expense | G20: Software Subscriptions | I20: 0 | J20: 55 | K20: =I20-J20 -> -55 | L20: Yes | N20: =IF(COUNTIF($A$2:$A$54,A20)>1,1,0) -> 0 | O20: ="Q"&ROUNDUP(MONTH($B20)/3,0) -> Q1
A21: TX-1019 | B21: 46056 | C21: Feb 2026 | D21: Twitch monthly payout | E21: Checking | F21: Revenue | G21: Subscriptions | H21: Twitch | I21: 1580 | J21: 0 | K21: =I21-J21 -> 1580 | L21: Yes | N21: =IF(COUNTIF($A$2:$A$54,A21)>1,1,0) -> 0 | O21: ="Q"&ROUNDUP(MONTH($B21)/3,0) -> Q1
A22: TX-1025 | B22: 46057 | C22: Feb 2026 | D22: Twitch platform service fees | E22: Checking | F22: Expense | G22: Platform Fees | I22: 0 | J22: 230 | K22: =I22-J22 -> -230 | L22: Yes | N22: =IF(COUNTIF($A$2:$A$54,A22)>1,1,0) -> 0 | O22: ="Q"&ROUNDUP(MONTH($B22)/3,0) -> Q1
A23: TX-1020 | B23: 46058 | C23: Feb 2026 | D23: Streamlabs creator tips | E23: PayPal | F23: Revenue | G23: Donations & Tips | H23: Donations | I23: 445 | J23: 0 | K23: =I23-J23 -> 445 | L23: Yes | N23: =IF(COUNTIF($A$2:$A$54,A23)>1,1,0) -> 0 | O23: ="Q"&ROUNDUP(MONTH($B23)/3,0) -> Q1
A24: TX-1028 | B24: 46060 | C24: Feb 2026 | D24: StreamYard subscription | E24: Credit Card | F24: Expense | G24: Software Subscriptions | I24: 0 | J24: 29 | K24: =I24-J24 -> -29 | L24: Yes | N24: =IF(COUNTIF($A$2:$A$54,A24)>1,1,0) -> 0 | O24: ="Q"&ROUNDUP(MONTH($B24)/3,0) -> Q1
A25: TX-1021 | B25: 46061 | C25: Feb 2026 | D25: Sponsored stream campaign | E25: Checking | F25: Revenue | G25: Sponsorships | H25: Brand Partnership | I25: 1500 | J25: 0 | K25: =I25-J25 -> 1500 | L25: Yes | N25: =IF(COUNTIF($A$2:$A$54,A25)>1,1,0) -> 0 | O25: ="Q"&ROUNDUP(MONTH($B25)/3,0) -> Q1
A26: TX-1029 | B26: 46062 | C26: Feb 2026 | D26: Canva Pro subscription | E26: Credit Card | F26: Expense | G26: Software Subscriptions | I26: 0 | J26: 15 | K26: =I26-J26 -> -15 | L26: Yes | N26: =IF(COUNTIF($A$2:$A$54,A26)>1,1,0) -> 0 | O26: ="Q"&ROUNDUP(MONTH($B26)/3,0) -> Q1
A27: TX-1022 | B27: 46065 | C27: Feb 2026 | D27: Shopify merchandise settlement | E27: Checking | F27: Revenue | G27: Merchandise | H27: Online Store | I27: 720 | J27: 0 | K27: =I27-J27 -> 720 | L27: Yes | N27: =IF(COUNTIF($A$2:$A$54,A27)>1,1,0) -> 0 | O27: ="Q"&ROUNDUP(MONTH($B27)/3,0) -> Q1
A28: TX-1026 | B28: 46065 | C28: Feb 2026 | D28: Stripe processing fees | E28: Checking | F28: Expense | G28: Payment Processing | I28: 0 | J28: 22 | K28: =I28-J28 -> -22 | L28: Yes | N28: =IF(COUNTIF($A$2:$A$54,A28)>1,1,0) -> 0 | O28: ="Q"&ROUNDUP(MONTH($B28)/3,0) -> Q1
A29: TX-1023 | B29: 46068 | C29: Feb 2026 | D29: Amazon affiliate payout | E29: Checking | F29: Revenue | G29: Affiliate Revenue | H29: Affiliate | I29: 132 | J29: 0 | K29: =I29-J29 -> 132 | L29: Yes | N29: =IF(COUNTIF($A$2:$A$54,A29)>1,1,0) -> 0 | O29: ="Q"&ROUNDUP(MONTH($B29)/3,0) -> Q1
A30: TX-1030 | B30: 46069 | C30: Feb 2026 | D30: Games and stream content | E30: Credit Card | F30: Expense | G30: Content & Games | I30: 0 | J30: 110 | K30: =I30-J30 -> -110 | L30: Yes | N30: =IF(COUNTIF($A$2:$A$54,A30)>1,1,0) -> 0 | O30: ="Q"&ROUNDUP(MONTH($B30)/3,0) -> Q1
A31: TX-1031 | B31: 46071 | C31: Feb 2026 | D31: Business internet allocation | E31: Checking | F31: Expense | G31: Internet | I31: 0 | J31: 120 | K31: =I31-J31 -> -120 | L31: Yes | M31: Business-use portion | N31: =IF(COUNTIF($A$2:$A$54,A31)>1,1,0) -> 0 | O31: ="Q"&ROUNDUP(MONTH($B31)/3,0) -> Q1
A32: TX-1024 | B32: 46073 | C32: Feb 2026 | D32: YouTube advertising payout | E32: Checking | F32: Revenue | G32: Ad Revenue | H32: YouTube | I32: 245 | J32: 0 | K32: =I32-J32 -> 245 | L32: Yes | N32: =IF(COUNTIF($A$2:$A$54,A32)>1,1,0) -> 0 | O32: ="Q"&ROUNDUP(MONTH($B32)/3,0) -> Q1
A33: TX-1032 | B33: 46075 | C33: Feb 2026 | D33: Social media campaign | E33: Credit Card | F33: Expense | G33: Advertising | I33: 0 | J33: 425 | K33: =I33-J33 -> -425 | L33: Yes | N33: =IF(COUNTIF($A$2:$A$54,A33)>1,1,0) -> 0 | O33: ="Q"&ROUNDUP(MONTH($B33)/3,0) -> Q1
A34: TX-1033 | B34: 46078 | C34: Feb 2026 | D34: Freelance video editing | E34: Checking | F34: Expense | G34: Contractor Services | I34: 0 | J34: 78 | K34: =I34-J34 -> -78 | L34: Yes | N34: =IF(COUNTIF($A$2:$A$54,A34)>1,1,0) -> 0 | O34: ="Q"&ROUNDUP(MONTH($B34)/3,0) -> Q1
A35: TX-1034 | B35: 46080 | C35: Feb 2026 | D35: Merchandise shipping labels | E35: Checking | F35: Expense | G35: Shipping & Postage | I35: 0 | J35: 38 | K35: =I35-J35 -> -38 | L35: Yes | N35: =IF(COUNTIF($A$2:$A$54,A35)>1,1,0) -> 0 | O35: ="Q"&ROUNDUP(MONTH($B35)/3,0) -> Q1
A36: TX-1035 | B36: 46081 | C36: Feb 2026 | D36: Packaging and printer supplies | E36: Credit Card | F36: Expense | G36: Office Supplies | I36: 0 | J36: 35 | K36: =I36-J36 -> -35 | L36: Yes | N36: =IF(COUNTIF($A$2:$A$54,A36)>1,1,0) -> 0 | O36: ="Q"&ROUNDUP(MONTH($B36)/3,0) -> Q1
A37: TX-1044 | B37: 46083 | C37: Mar 2026 | D37: Adobe Creative Cloud | E37: Credit Card | F37: Expense | G37: Software Subscriptions | I37: 0 | J37: 55 | K37: =I37-J37 -> -55 | L37: Yes | N37: =IF(COUNTIF($A$2:$A$54,A37)>1,1,0) -> 0 | O37: ="Q"&ROUNDUP(MONTH($B37)/3,0) -> Q1
A38: TX-1036 | B38: 46084 | C38: Mar 2026 | D38: Twitch monthly payout | E38: Checking | F38: Revenue | G38: Subscriptions | H38: Twitch | I38: 1710 | J38: 0 | K38: =I38-J38 -> 1710 | L38: Yes | N38: =IF(COUNTIF($A$2:$A$54,A38)>1,1,0) -> 0 | O38: ="Q"&ROUNDUP(MONTH($B38)/3,0) -> Q1
A39: TX-1042 | B39: 46085 | C39: Mar 2026 | D39: Twitch platform service fees | E39: Checking | F39: Expense | G39: Platform Fees | I39: 0 | J39: 240 | K39: =I39-J39 -> -240 | L39: Yes | N39: =IF(COUNTIF($A$2:$A$54,A39)>1,1,0) -> 0 | O39: ="Q"&ROUNDUP(MONTH($B39)/3,0) -> Q1
A40: TX-1037 | B40: 46086 | C40: Mar 2026 | D40: Streamlabs creator tips | E40: PayPal | F40: Revenue | G40: Donations & Tips | H40: Donations | I40: 510 | J40: 0 | K40: =I40-J40 -> 510 | L40: Yes | N40: =IF(COUNTIF($A$2:$A$54,A40)>1,1,0) -> 0 | O40: ="Q"&ROUNDUP(MONTH($B40)/3,0) -> Q1
...

Sheet COA & Category Map
A1: Merchant / Source | B1: Type | C1: Mapped Category | E1: Account Number | F1: Account Name | G1: Account Type | H1: Normal Balance | I1: Ledger Field | J1: Matching Label | K1: Transaction Count | M1: Account Type | N1: Number of Accounts
A2: Twitch Payout | B2: Revenue | C2: Subscriptions | E2: 1000 | F2: Checking | G2: Asset | H2: Debit | I2: Account | J2: Checking | K2: =IF(J2="",0,IF(I2="Account",COUNTIF(Transactions!$E:$E,J2),COUNTIF(Transactions!$G:$G,J2))) -> 109 | M2: Asset | N2: =COUNTIF($G$2:$G$30,M2) -> 4
A3: Streamlabs | B3: Revenue | C3: Donations & Tips | E3: 1010 | F3: PayPal | G3: Asset | H3: Debit | I3: Account | J3: PayPal | K3: =IF(J3="",0,IF(I3="Account",COUNTIF(Transactions!$E:$E,J3),COUNTIF(Transactions!$G:$G,J3))) -> 12 | M3: Contra Asset | N3: =COUNTIF($G$2:$G$30,M3) -> 1
A4: Brand Partner | B4: Revenue | C4: Sponsorships | E4: 1100 | F4: Accounts Receivable | G4: Asset | H4: Debit | K4: =IF(J4="",0,IF(I4="Account",COUNTIF(Transactions!$E:$E,J4),COUNTIF(Transactions!$G:$G,J4))) -> 0 | M4: Liability | N4: =COUNTIF($G$2:$G$30,M4) -> 3
A5: Shopify | B5: Revenue | C5: Merchandise | E5: 1500 | F5: Equipment - Capital Assets | G5: Asset | H5: Debit | K5: =IF(J5="",0,IF(I5="Account",COUNTIF(Transactions!$E:$E,J5),COUNTIF(Transactions!$G:$G,J5))) -> 0 | M5: Equity | N5: =COUNTIF($G$2:$G$30,M5) -> 3
A6: Amazon Associates | B6: Revenue | C6: Affiliate Revenue | E6: 1590 | F6: Accumulated Depreciation | G6: Contra Asset | H6: Credit | K6: =IF(J6="",0,IF(I6="Account",COUNTIF(Transactions!$E:$E,J6),COUNTIF(Transactions!$G:$G,J6))) -> 0 | M6: Revenue | N6: =COUNTIF($G$2:$G$30,M6) -> 6
A7: YouTube | B7: Revenue | C7: Ad Revenue | E7: 2000 | F7: Credit Card Payable | G7: Liability | H7: Credit | I7: Account | J7: Credit Card | K7: =IF(J7="",0,IF(I7="Account",COUNTIF(Transactions!$E:$E,J7),COUNTIF(Transactions!$G:$G,J7))) -> 53 | M7: Expense | N7: =COUNTIF($G$2:$G$30,M7) -> 12
A8: Twitch Fee | B8: Expense | C8: Platform Fees | E8: 2100 | F8: Accounts Payable | G8: Liability | H8: Credit | K8: =IF(J8="",0,IF(I8="Account",COUNTIF(Transactions!$E:$E,J8),COUNTIF(Transactions!$G:$G,J8))) -> 0
A9: Stripe Fee | B9: Expense | C9: Payment Processing | E9: 2200 | F9: Sales Tax Payable | G9: Liability | H9: Credit | K9: =IF(J9="",0,IF(I9="Account",COUNTIF(Transactions!$E:$E,J9),COUNTIF(Transactions!$G:$G,J9))) -> 0
A10: Adobe | B10: Expense | C10: Software Subscriptions | E10: 3000 | F10: Owner Contribution | G10: Equity | H10: Credit | I10: Category | J10: Owner Contribution | K10: =IF(J10="",0,IF(I10="Account",COUNTIF(Transactions!$E:$E,J10),COUNTIF(Transactions!$G:$G,J10))) -> 0
A11: StreamYard | B11: Expense | C11: Software Subscriptions | E11: 3100 | F11: Owner Draw | G11: Equity | H11: Debit | I11: Category | J11: Owner Draw | K11: =IF(J11="",0,IF(I11="Account",COUNTIF(Transactions!$E:$E,J11),COUNTIF(Transactions!$G:$G,J11))) -> 0
A12: Canva | B12: Expense | C12: Software Subscriptions | E12: 3200 | F12: Retained Earnings | G12: Equity | H12: Credit | K12: =IF(J12="",0,IF(I12="Account",COUNTIF(Transactions!$E:$E,J12),COUNTIF(Transactions!$G:$G,J12))) -> 0
A13: Best Buy | B13: Expense | C13: Equipment | E13: 4000 | F13: Subscriptions | G13: Revenue | H13: Credit | I13: Category | J13: Subscriptions | K13: =IF(J13="",0,IF(I13="Account",COUNTIF(Transactions!$E:$E,J13),COUNTIF(Transactions!$G:$G,J13))) -> 12
A14: Steam | B14: Expense | C14: Content & Games | E14: 4010 | F14: Donations & Tips | G14: Revenue | H14: Credit | I14: Category | J14: Donations & Tips | K14: =IF(J14="",0,IF(I14="Account",COUNTIF(Transactions!$E:$E,J14),COUNTIF(Transactions!$G:$G,J14))) -> 12
A15: Comcast | B15: Expense | C15: Internet | E15: 4020 | F15: Sponsorships | G15: Revenue | H15: Credit | I15: Category | J15: Sponsorships | K15: =IF(J15="",0,IF(I15="Account",COUNTIF(Transactions!$E:$E,J15),COUNTIF(Transactions!$G:$G,J15))) -> 12
A16: Meta Ads | B16: Expense | C16: Advertising | E16: 4030 | F16: Merchandise | G16: Revenue | H16: Credit | I16: Category | J16: Merchandise | K16: =IF(J16="",0,IF(I16="Account",COUNTIF(Transactions!$E:$E,J16),COUNTIF(Transactions!$G:$G,J16))) -> 12
A17: Video Editor | B17: Expense | C17: Contractor Services | E17: 4040 | F17: Affiliate Revenue | G17: Revenue | H17: Credit | I17: Category | J17: Affiliate Revenue | K17: =IF(J17="",0,IF(I17="Account",COUNTIF(Transactions!$E:$E,J17),COUNTIF(Transactions!$G:$G,J17))) -> 12
A18: USPS | B18: Expense | C18: Shipping & Postage | E18: 4050 | F18: Ad Revenue | G18: Revenue | H18: Credit | I18: Category | J18: Ad Revenue | K18: =IF(J18="",0,IF(I18="Account",COUNTIF(Transactions!$E:$E,J18),COUNTIF(Transactions!$G:$G,J18))) -> 12
A19: Office Depot | B19: Expense | C19: Office Supplies | E19: 5000 | F19: Platform Fees | G19: Expense | H19: Debit | I19: Category | J19: Platform Fees | K19: =IF(J19="",0,IF(I19="Account",COUNTIF(Transactions!$E:$E,J19),COUNTIF(Transactions!$G:$G,J19))) -> 12
E20: 5010 | F20: Payment Processing | G20: Expense | H20: Debit | I20: Category | J20: Payment Processing | K20: =IF(J20="",0,IF(I20="Account",COUNTIF(Transactions!$E:$E,J20),COUNTIF(Transactions!$G:$G,J20))) -> 12
E21: 5020 | F21: Software Subscriptions | G21: Expense | H21: Debit | I21: Category | J21: Software Subscriptions | K21: =IF(J21="",0,IF(I21="Account",COUNTIF(Transactions!$E:$E,J21),COUNTIF(Transactions!$G:$G,J21))) -> 24
E22: 5030 | F22: Content & Games | G22: Expense | H22: Debit | I22: Category | J22: Content & Games | K22: =IF(J22="",0,IF(I22="Account",COUNTIF(Transactions!$E:$E,J22),COUNTIF(Transactions!$G:$G,J22))) -> 9
E23: 5040 | F23: Internet | G23: Expense | H23: Debit | I23: Category | J23: Internet | K23: =IF(J23="",0,IF(I23="Account",COUNTIF(Transactions!$E:$E,J23),COUNTIF(Transactions!$G:$G,J23))) -> 10
E24: 5050 | F24: Advertising | G24: Expense | H24: Debit | I24: Category | J24: Advertising | K24: =IF(J24="",0,IF(I24="Account",COUNTIF(Transactions!$E:$E,J24),COUNTIF(Transactions!$G:$G,J24))) -> 10
E25: 5060 | F25: Contractor Services | G25: Expense | H25: Debit | I25: Category | J25: Contractor Services | K25: =IF(J25="",0,IF(I25="Account",COUNTIF(Transactions!$E:$E,J25),COUNTIF(Transactions!$G:$G,J25))) -> 8
E26: 5070 | F26: Shipping & Postage | G26: Expense | H26: Debit | I26: Category | J26: Shipping & Postage | K26: =IF(J26="",0,IF(I26="Account",COUNTIF(Transactions!$E:$E,J26),COUNTIF(Transactions!$G:$G,J26))) -> 7
E27: 5080 | F27: Office Supplies | G27: Expense | H27: Debit | I27: Category | J27: Office Supplies | K27: =IF(J27="",0,IF(I27="Account",COUNTIF(Transactions!$E:$E,J27),COUNTIF(Transactions!$G:$G,J27))) -> 6
E28: 5090 | F28: Equipment Expense | G28: Expense | H28: Debit | I28: Category | J28: Equipment | K28: =IF(J28="",0,IF(I28="Account",COUNTIF(Transactions!$E:$E,J28),COUNTIF(Transactions!$G:$G,J28))) -> 4
E29: 5100 | F29: Depreciation Expense | G29: Expense | H29: Debit | K29: =IF(J29="",0,IF(I29="Account",COUNTIF(Transactions!$E:$E,J29),COUNTIF(Transactions!$G:$G,J29))) -> 0
E30: 5110 | F30: Travel & Events | G30: Expense | H30: Debit | K30: =IF(J30="",0,IF(I30="Account",COUNTIF(Transactions!$E:$E,J30),COUNTIF(Transactions!$G:$G,J30))) -> 0

Sheet Project Notes
B2: Creator Bookkeeping Portfolio Case Study
B4: Client | C4: Pixel & Pastry Media (fictional creator business)
B5: Prepared by | C5: Blackthorn Ledger
B6: Period | C6: January–December 2026
B7: Challenge | C7: Income arrived through six channels while expenses crossed bank, card, PayPal, and platform accounts.
B8: Work completed | C8: Standardized and categorized 174 transactions, developed a 29-account Chart of Accounts, reconciled annual source totals, produced quarterly and annual profit-and-loss reporting, and created an automated management dashboard.
B9: Result | C9: Delivered a complete 12-month bookkeeping system with $77,602 in revenue, $16,650 in expenses, $60,952 in net income, revenue-mix analysis, automated audit checks, and repeatable monthly reporting.
B10: Disclosure | C10: All names, transactions, and financial results are simulated for portfolio demonstration purposes.
B13: Resume-ready bullets
B14: • Built a Google Sheets bookkeeping system for a simulated creator business, organizing and categorizing 174 transactions across six revenue streams and ten expense categories.
B15: • Developed a 29-account Chart of Accounts, four quarterly profit-and-loss statements, and a full-year dashboard tracking revenue, expenses, net income, profit margin, and revenue mix.
B16: • Reconciled transaction-level inflows and outflows to annual reporting totals of $77,602 in revenue and $16,650 in expenses, with zero uncategorized or duplicate transactions.

Sheet Bank Reconciliation
A1: Pixel & Pastry Media
A2: Bank Reconciliation
A3: As of | B3: 46387
A5: Account | B5: Book Balance | C5: Statement Balance | D5: Deposits in Transit | E5: Outstanding Payments | F5: Adjusted Bank Balance | G5: Difference | H5: Status
A6: Checking | B6: 64127 | C6: 64012 | D6: =SUMIFS($E$11:$E1000,$A$11:$A1000,$A6,$B$11:$B1000,"Deposit in Transit") -> 850 | E6: =SUMIFS($E$11:$E1000,$A$11:$A1000,$A6,$B$11:$B1000,"Outstanding Payment") -> 735 | F6: =C6+D6-E6 -> 64127 | G6: =B6-F6 -> 0 | H6: =IF(ABS(G6)<0.01,"RECONCILED","REVIEW") -> RECONCILED
A7: Paypal | B7: 7165 | C7: 7095 | D7: 120 | E7: 50 | F7: =C7+D7-E7 -> 7165 | G7: =B7-F7 -> 0 | H7: =IF(ABS(G7)<0.01,"RECONCILED","REVIEW") -> RECONCILED
A9: Reconciliation Items
A10: Account | B10: Type | C10: Reference | D10: Date | E10: Amount
A11: Checking | B11: Deposit in Transit | C11: December sponsorship payment | D11: 46387 | E11: 500
A12: Checking | B12: Deposit in Transit | C12: Merchandise settlement | D12: 46387 | E12: 350
A13: Checking | B13: Outstanding Payment | C13: Freelance video editing | D13: 46385 | E13: 420
A14: Checking | B14: Outstanding Payment | C14: Advertising invoice | D14: 46386 | E14: 315
A15: PayPal | B15: Deposit in Transit | C15: Streamlabs creator tips | D15: 46387 | E15: 120
A16: PayPal | B16: Outstanding Payment | C16: Software subscription | D16: 46386 | E16: 50
